Workbook
Name margin_rate: Assumptions!$B$1
Name max_rate: Assumptions!$K$1
Name region: Assumptions!$J$11:$J$14
Name seeding: Assumptions!$K$11:$K$14
Name step: Assumptions!$E$12:$E$16
Name target: Assumptions!$K$5
Name tier_floor: Assumptions!$A$12:$A$16
Name tier_rate: Assumptions!$D$12:$D$16
Name warning_level: Assumptions!$K$2
Name Within_reach: Assumptions!$B$19

Sheet README
B1: Quota model - README
B3: Business Question
B5: Does the flat-tier commission structure overpay, and if so, where and by how much?
B7: Findings
B9: The flat commission structure paid about $5.5 million more than a marginal
B10: structure would have over 2021 to 2025. The annual overpay grew from about
B11: $0.64 million in the first year to $1.57 million in the last, and it grew every year.
B12: Over the same period (2021-2025) commissions more than doubled, while margin dollars
B13: grew only 62% and quota attainment stayed steady near 100%.
B15: Tabs
B17: Assumptions: | D17: Listing of all standards for each formula. Each number is tagged back
D18: to a Rule in the rules_spec.md
B19: Rep_month: | D19: Table with rep, region, date, pay information
B20: Sales and margins: | D20: Table of net sales by region by year
D21: Table of margin dollars by region and by year
B22: Commissions: | D22: Table of flat commission dollars by region and by year
D23: Table of flat commission rates/margin dollars by region and by year
B24: Overpay: | D24: Table of overpay by region and by year
D25: Table of overpay per rep month by region and year
B26: Quota: | D26: Table of Net sales by region by month and year
D27: Table for quota by region by month and year
D28: Table of quota attainment by region by month and year
B29: Cliff exposure: | D29: Table showing the number of rep-months within 5% of each tier
D30: and the cost exposure
B31: Scenarios: | D31: Table of margin dollars and a comparison of commission plan
D32: payouts over the years
D33: Table comparing blended flat / indexed_flat / marginal rates
D34: divided by margin dollars
D35: Table showing company savings comparing blended flat to
D36: indexed_flat / marginal
B37: Checks: | D37: Validation of calculations
B38: Charts: | D38: Visualization of Overpay dollars per year
D39: Visualization of payout rate comparison between plans
D40: Visualization of commission growth vs margin dollar growth
B42: Coloration
B44: Numbering
B45: Hard-coded numbering
B46: calculated numbering
B48: Data
B50: All data is synthetic and created for the purpose of gaining practice with various advanced
...

Sheet Assumptions
A1: Margin_rate | B1: 0.5 | C1: Rule Spec, Item #3 | J1: Max Commission Rate: | K1: 0.6 | L1: Rule Spec, Item #4
J2: Warning Line: | K2: 0.45 | L2: Rule Spec, Item #4
J5: Growth_target | K5: 0.15 | L5: Rule Spec, Item #6
B10: Tier_table | D10: Rule Spec, Item #4 | J10: Year 1 quota seed by region | L10: Rule Spec, Item #6
A11: Tier_floor | D11: Tier_rate | E11: Rate_step | J11: 1 | K11: 150000
A12: 0 | D12: 0.25 | E12: =$D12 -> 0.25 | J12: 2 | K12: 275000
A13: 25000 | D13: 0.33 | E13: =$D13-$D12 -> 0.08 | J13: 3 | K13: 300000
A14: 50000 | D14: 0.42 | E14: =$D14-$D13 -> 0.09 | J14: 4 | K14: 400000
A15: 75000 | D15: 0.51 | E15: =$D15-$D14 -> 0.09
A16: 100000 | D16: 0.6 | E16: =$D16-$D15 -> 0.09
A19: Within reach | B19: 0.05 | C19: of the band edge

Sheet Rep_month
A1: rep_id | B1: region_id | C1: net_sales | D1: month_start | E1: rate | F1: margin_dollars | G1: flat_commission | H1: marginal_commission | I1: overpay | J1: year | K1: index_factor | L1: indexed_rate | M1: indexed_commission
A2: R001 | B2: 4 | C2: 56783.25 | D2: 44197 | E2: =_xlfn.XLOOKUP(C2,tier_floor,tier_rate,,-1) -> 0.42 | F2: =C2*margin_rate -> 28391.625 | G2: =F2*E2 -> 11924.483 | H2: {=SUMPRODUCT((C2>tier_floor)*((C2-tier_floor)*step)*margin_rate)} -> 8674.4825 | I2: =G2-H2 -> 3250 | J2: =YEAR(D2) -> 2021 | K2: =(1+target)^($J2-(MIN(tbl_rep_mon[year]))) -> 1 | L2: =_xlfn.XLOOKUP(($C2/$K2),tier_floor,tier_rate,,-1) -> 0.42 | M2: =$F2*$L2 -> 11924.483
A3: R002 | B3: 2 | C3: 36514.31 | D3: 44197 | E3: =_xlfn.XLOOKUP(C3,tier_floor,tier_rate,,-1) -> 0.33 | F3: =C3*margin_rate -> 18257.155 | G3: =F3*E3 -> 6024.8611 | H3: {=SUMPRODUCT((C3>tier_floor)*((C3-tier_floor)*step)*margin_rate)} -> 5024.8611 | I3: =G3-H3 -> 1000 | J3: =YEAR(D3) -> 2021 | K3: =(1+target)^($J3-(MIN(tbl_rep_mon[year]))) -> 1 | L3: =_xlfn.XLOOKUP(($C3/$K3),tier_floor,tier_rate,,-1) -> 0.33 | M3: =$F3*$L3 -> 6024.8611
A4: R003 | B4: 2 | C4: 47767.8 | D4: 44197 | E4: =_xlfn.XLOOKUP(C4,tier_floor,tier_rate,,-1) -> 0.33 | F4: =C4*margin_rate -> 23883.9 | G4: =F4*E4 -> 7881.687 | H4: {=SUMPRODUCT((C4>tier_floor)*((C4-tier_floor)*step)*margin_rate)} -> 6881.687 | I4: =G4-H4 -> 1000 | J4: =YEAR(D4) -> 2021 | K4: =(1+target)^($J4-(MIN(tbl_rep_mon[year]))) -> 1 | L4: =_xlfn.XLOOKUP(($C4/$K4),tier_floor,tier_rate,,-1) -> 0.33 | M4: =$F4*$L4 -> 7881.687
A5: R004 | B5: 4 | C5: 37877.29 | D5: 44197 | E5: =_xlfn.XLOOKUP(C5,tier_floor,tier_rate,,-1) -> 0.33 | F5: =C5*margin_rate -> 18938.645 | G5: =F5*E5 -> 6249.7529 | H5: {=SUMPRODUCT((C5>tier_floor)*((C5-tier_floor)*step)*margin_rate)} -> 5249.7528 | I5: =G5-H5 -> 1000 | J5: =YEAR(D5) -> 2021 | K5: =(1+target)^($J5-(MIN(tbl_rep_mon[year]))) -> 1 | L5: =_xlfn.XLOOKUP(($C5/$K5),tier_floor,tier_rate,,-1) -> 0.33 | M5: =$F5*$L5 -> 6249.7529
A6: R005 | B6: 4 | C6: 46326.78 | D6: 44197 | E6: =_xlfn.XLOOKUP(C6,tier_floor,tier_rate,,-1) -> 0.33 | F6: =C6*margin_rate -> 23163.39 | G6: =F6*E6 -> 7643.9187 | H6: {=SUMPRODUCT((C6>tier_floor)*((C6-tier_floor)*step)*margin_rate)} -> 6643.9187 | I6: =G6-H6 -> 1000 | J6: =YEAR(D6) -> 2021 | K6: =(1+target)^($J6-(MIN(tbl_rep_mon[year]))) -> 1 | L6: =_xlfn.XLOOKUP(($C6/$K6),tier_floor,tier_rate,,-1) -> 0.33 | M6: =$F6*$L6 -> 7643.9187
A7: R006 | B7: 3 | C7: 46295.5 | D7: 44197 | E7: =_xlfn.XLOOKUP(C7,tier_floor,tier_rate,,-1) -> 0.33 | F7: =C7*margin_rate -> 23147.75 | G7: =F7*E7 -> 7638.7575 | H7: {=SUMPRODUCT((C7>tier_floor)*((C7-tier_floor)*step)*margin_rate)} -> 6638.7575 | I7: =G7-H7 -> 1000 | J7: =YEAR(D7) -> 2021 | K7: =(1+target)^($J7-(MIN(tbl_rep_mon[year]))) -> 1 | L7: =_xlfn.XLOOKUP(($C7/$K7),tier_floor,tier_rate,,-1) -> 0.33 | M7: =$F7*$L7 -> 7638.7575
A8: R007 | B8: 3 | C8: 70096.43 | D8: 44197 | E8: =_xlfn.XLOOKUP(C8,tier_floor,tier_rate,,-1) -> 0.42 | F8: =C8*margin_rate -> 35048.215 | G8: =F8*E8 -> 14720.25 | H8: {=SUMPRODUCT((C8>tier_floor)*((C8-tier_floor)*step)*margin_rate)} -> 11470.25 | I8: =G8-H8 -> 3250 | J8: =YEAR(D8) -> 2021 | K8: =(1+target)^($J8-(MIN(tbl_rep_mon[year]))) -> 1 | L8: =_xlfn.XLOOKUP(($C8/$K8),tier_floor,tier_rate,,-1) -> 0.42 | M8: =$F8*$L8 -> 14720.25
A9: R008 | B9: 1 | C9: 57392.57 | D9: 44197 | E9: =_xlfn.XLOOKUP(C9,tier_floor,tier_rate,,-1) -> 0.42 | F9: =C9*margin_rate -> 28696.285 | G9: =F9*E9 -> 12052.44 | H9: {=SUMPRODUCT((C9>tier_floor)*((C9-tier_floor)*step)*margin_rate)} -> 8802.4397 | I9: =G9-H9 -> 3250 | J9: =YEAR(D9) -> 2021 | K9: =(1+target)^($J9-(MIN(tbl_rep_mon[year]))) -> 1 | L9: =_xlfn.XLOOKUP(($C9/$K9),tier_floor,tier_rate,,-1) -> 0.42 | M9: =$F9*$L9 -> 12052.44
A10: R009 | B10: 2 | C10: 56245.62 | D10: 44197 | E10: =_xlfn.XLOOKUP(C10,tier_floor,tier_rate,,-1) -> 0.42 | F10: =C10*margin_rate -> 28122.81 | G10: =F10*E10 -> 11811.58 | H10: {=SUMPRODUCT((C10>tier_floor)*((C10-tier_floor)*step)*margin_rate)} -> 8561.5802 | I10: =G10-H10 -> 3250 | J10: =YEAR(D10) -> 2021 | K10: =(1+target)^($J10-(MIN(tbl_rep_mon[year]))) -> 1 | L10: =_xlfn.XLOOKUP(($C10/$K10),tier_floor,tier_rate,,-1) -> 0.42 | M10: =$F10*$L10 -> 11811.58
A11: R010 | B11: 2 | C11: 61291.26 | D11: 44197 | E11: =_xlfn.XLOOKUP(C11,tier_floor,tier_rate,,-1) -> 0.42 | F11: =C11*margin_rate -> 30645.63 | G11: =F11*E11 -> 12871.165 | H11: {=SUMPRODUCT((C11>tier_floor)*((C11-tier_floor)*step)*margin_rate)} -> 9621.1646 | I11: =G11-H11 -> 3250 | J11: =YEAR(D11) -> 2021 | K11: =(1+target)^($J11-(MIN(tbl_rep_mon[year]))) -> 1 | L11: =_xlfn.XLOOKUP(($C11/$K11),tier_floor,tier_rate,,-1) -> 0.42 | M11: =$F11*$L11 -> 12871.165
A12: R011 | B12: 4 | C12: 56554.38 | D12: 44197 | E12: =_xlfn.XLOOKUP(C12,tier_floor,tier_rate,,-1) -> 0.42 | F12: =C12*margin_rate -> 28277.19 | G12: =F12*E12 -> 11876.42 | H12: {=SUMPRODUCT((C12>tier_floor)*((C12-tier_floor)*step)*margin_rate)} -> 8626.4198 | I12: =G12-H12 -> 3250 | J12: =YEAR(D12) -> 2021 | K12: =(1+target)^($J12-(MIN(tbl_rep_mon[year]))) -> 1 | L12: =_xlfn.XLOOKUP(($C12/$K12),tier_floor,tier_rate,,-1) -> 0.42 | M12: =$F12*$L12 -> 11876.42
A13: R012 | B13: 3 | C13: 61783.9 | D13: 44197 | E13: =_xlfn.XLOOKUP(C13,tier_floor,tier_rate,,-1) -> 0.42 | F13: =C13*margin_rate -> 30891.95 | G13: =F13*E13 -> 12974.619 | H13: {=SUMPRODUCT((C13>tier_floor)*((C13-tier_floor)*step)*margin_rate)} -> 9724.619 | I13: =G13-H13 -> 3250 | J13: =YEAR(D13) -> 2021 | K13: =(1+target)^($J13-(MIN(tbl_rep_mon[year]))) -> 1 | L13: =_xlfn.XLOOKUP(($C13/$K13),tier_floor,tier_rate,,-1) -> 0.42 | M13: =$F13*$L13 -> 12974.619
... A1201: R049 | B1201: 4 | C1201: 18895.32 | D1201: 45992 | E1201: =_xlfn.XLOOKUP(C1201,tier_floor,tier_rate,,-1) -> 0.25 | F1201: =C1201*margin_rate -> 9447.66 | G1201: =F1201*E1201 -> 2361.915 | H1201: {=SUMPRODUCT((C1201>tier_floor)*((C1201-tier_floor)*step)*margin_rate)} -> 2361.915 | I1201: =G1201-H1201 -> 0 | J1201: =YEAR(D1201) -> 2025 | K1201: =(1+target)^($J1201-(MIN(tbl_rep_mon[year]))) -> 1.7490062 | L1201: =_xlfn.XLOOKUP(($C1201/$K1201),tier_floor,tier_rate,,-1) -> 0.25 | M1201: =$F1201*$L1201 -> 2361.915

Sheet Sales and margins
A1: Net Sales
B2: Year | H2: net sales by region
A3: Region | B3: 2021 | C3: 2022 | D3: 2023 | E3: 2024 | F3: 2025
A4: 1 | B4: =SUMIFS(tbl_rep_mon[net_sales],tbl_rep_mon[region_id],$A4,tbl_rep_mon[year],B$3) -> 1645566.7 | C4: =SUMIFS(tbl_rep_mon[net_sales],tbl_rep_mon[region_id],$A4,tbl_rep_mon[year],C$3) -> 2181271.3 | D4: =SUMIFS(tbl_rep_mon[net_sales],tbl_rep_mon[region_id],$A4,tbl_rep_mon[year],D$3) -> 2475349.1 | E4: =SUMIFS(tbl_rep_mon[net_sales],tbl_rep_mon[region_id],$A4,tbl_rep_mon[year],E$3) -> 3037173.1 | F4: =SUMIFS(tbl_rep_mon[net_sales],tbl_rep_mon[region_id],$A4,tbl_rep_mon[year],F$3) -> 3612056.6 | H4: =SUM(B4:F4) -> 12951417
A5: 2 | B5: =SUMIFS(tbl_rep_mon[net_sales],tbl_rep_mon[region_id],$A5,tbl_rep_mon[year],B$3) -> 3092124.3 | C5: =SUMIFS(tbl_rep_mon[net_sales],tbl_rep_mon[region_id],$A5,tbl_rep_mon[year],C$3) -> 3682088.9 | D5: =SUMIFS(tbl_rep_mon[net_sales],tbl_rep_mon[region_id],$A5,tbl_rep_mon[year],D$3) -> 4223276 | E5: =SUMIFS(tbl_rep_mon[net_sales],tbl_rep_mon[region_id],$A5,tbl_rep_mon[year],E$3) -> 5056134.4 | F5: =SUMIFS(tbl_rep_mon[net_sales],tbl_rep_mon[region_id],$A5,tbl_rep_mon[year],F$3) -> 5422073.2 | H5: =SUM(B5:F5) -> 21475697
A6: 3 | B6: =SUMIFS(tbl_rep_mon[net_sales],tbl_rep_mon[region_id],$A6,tbl_rep_mon[year],B$3) -> 3683991.1 | C6: =SUMIFS(tbl_rep_mon[net_sales],tbl_rep_mon[region_id],$A6,tbl_rep_mon[year],C$3) -> 3770064.4 | D6: =SUMIFS(tbl_rep_mon[net_sales],tbl_rep_mon[region_id],$A6,tbl_rep_mon[year],D$3) -> 4328408.6 | E6: =SUMIFS(tbl_rep_mon[net_sales],tbl_rep_mon[region_id],$A6,tbl_rep_mon[year],E$3) -> 4430181.1 | F6: =SUMIFS(tbl_rep_mon[net_sales],tbl_rep_mon[region_id],$A6,tbl_rep_mon[year],F$3) -> 4925943.5 | H6: =SUM(B6:F6) -> 21138589
A7: 4 | B7: =SUMIFS(tbl_rep_mon[net_sales],tbl_rep_mon[region_id],$A7,tbl_rep_mon[year],B$3) -> 4719062.6 | C7: =SUMIFS(tbl_rep_mon[net_sales],tbl_rep_mon[region_id],$A7,tbl_rep_mon[year],C$3) -> 5074345.7 | D7: =SUMIFS(tbl_rep_mon[net_sales],tbl_rep_mon[region_id],$A7,tbl_rep_mon[year],D$3) -> 5960433.9 | E7: =SUMIFS(tbl_rep_mon[net_sales],tbl_rep_mon[region_id],$A7,tbl_rep_mon[year],E$3) -> 6622707.7 | F7: =SUMIFS(tbl_rep_mon[net_sales],tbl_rep_mon[region_id],$A7,tbl_rep_mon[year],F$3) -> 7382402.5 | H7: =SUM(B7:F7) -> 29758952
A8: Company | B8: =SUM($B4:$B7) -> 13140745 | C8: =SUM($C4:$C7) -> 14707770 | D8: =SUM($D4:$D7) -> 16987468 | E8: =SUM($E4:$E7) -> 19146196 | F8: =SUM($F4:$F7) -> 21342476 | H8: =SUM(B8:F8) -> 85324655
A10: Margin Dollars
B11: Year | H11: margin dollars by region
A12: Region | B12: 2021 | C12: 2022 | D12: 2023 | E12: 2024 | F12: 2025
A13: 1 | B13: =SUMIFS(tbl_rep_mon[margin_dollars],tbl_rep_mon[region_id],$A13, tbl_rep_mon[year],B$12) -> 822783.37 | C13: =SUMIFS(tbl_rep_mon[margin_dollars],tbl_rep_mon[region_id],$A13, tbl_rep_mon[year],C$12) -> 1090635.6 | D13: =SUMIFS(tbl_rep_mon[margin_dollars],tbl_rep_mon[region_id],$A13, tbl_rep_mon[year],D$12) -> 1237674.6 | E13: =SUMIFS(tbl_rep_mon[margin_dollars],tbl_rep_mon[region_id],$A13, tbl_rep_mon[year],E$12) -> 1518586.6 | F13: =SUMIFS(tbl_rep_mon[margin_dollars],tbl_rep_mon[region_id],$A13, tbl_rep_mon[year],F$12) -> 1806028.3 | H13: =SUM(B13:F13) -> 6475708.4
A14: 2 | B14: =SUMIFS(tbl_rep_mon[margin_dollars],tbl_rep_mon[region_id],$A14, tbl_rep_mon[year],B$12) -> 1546062.2 | C14: =SUMIFS(tbl_rep_mon[margin_dollars],tbl_rep_mon[region_id],$A14, tbl_rep_mon[year],C$12) -> 1841044.4 | D14: =SUMIFS(tbl_rep_mon[margin_dollars],tbl_rep_mon[region_id],$A14, tbl_rep_mon[year],D$12) -> 2111638 | E14: =SUMIFS(tbl_rep_mon[margin_dollars],tbl_rep_mon[region_id],$A14, tbl_rep_mon[year],E$12) -> 2528067.2 | F14: =SUMIFS(tbl_rep_mon[margin_dollars],tbl_rep_mon[region_id],$A14, tbl_rep_mon[year],F$12) -> 2711036.6 | H14: =SUM(B14:F14) -> 10737848
A15: 3 | B15: =SUMIFS(tbl_rep_mon[margin_dollars],tbl_rep_mon[region_id],$A15, tbl_rep_mon[year],B$12) -> 1841995.6 | C15: =SUMIFS(tbl_rep_mon[margin_dollars],tbl_rep_mon[region_id],$A15, tbl_rep_mon[year],C$12) -> 1885032.2 | D15: =SUMIFS(tbl_rep_mon[margin_dollars],tbl_rep_mon[region_id],$A15, tbl_rep_mon[year],D$12) -> 2164204.3 | E15: =SUMIFS(tbl_rep_mon[margin_dollars],tbl_rep_mon[region_id],$A15, tbl_rep_mon[year],E$12) -> 2215090.5 | F15: =SUMIFS(tbl_rep_mon[margin_dollars],tbl_rep_mon[region_id],$A15, tbl_rep_mon[year],F$12) -> 2462971.8 | H15: =SUM(B15:F15) -> 10569294
A16: 4 | B16: =SUMIFS(tbl_rep_mon[margin_dollars],tbl_rep_mon[region_id],$A16, tbl_rep_mon[year],B$12) -> 2359531.3 | C16: =SUMIFS(tbl_rep_mon[margin_dollars],tbl_rep_mon[region_id],$A16, tbl_rep_mon[year],C$12) -> 2537172.8 | D16: =SUMIFS(tbl_rep_mon[margin_dollars],tbl_rep_mon[region_id],$A16, tbl_rep_mon[year],D$12) -> 2980217 | E16: =SUMIFS(tbl_rep_mon[margin_dollars],tbl_rep_mon[region_id],$A16, tbl_rep_mon[year],E$12) -> 3311353.9 | F16: =SUMIFS(tbl_rep_mon[margin_dollars],tbl_rep_mon[region_id],$A16, tbl_rep_mon[year],F$12) -> 3691201.3 | H16: =SUM(B16:F16) -> 14879476
A17: Company | B17: =SUM($B13:$B16) -> 6570372.4 | C17: =SUM($C13:$C16) -> 7353885.1 | D17: =SUM($D13:$D16) -> 8493733.8 | E17: =SUM($E13:$E16) -> 9573098.2 | F17: =SUM($F13:$F16) -> 10671238 | H17: =SUM(B17:F17) -> 42662327

Sheet Commissions
A1: Flat commission
B2: Year
A3: Region | B3: 2021 | C3: 2022 | D3: 2023 | E3: 2024 | F3: 2025 | H3: Flat commission by region
A4: 1 | B4: =SUMIFS(tbl_rep_mon[flat_commission],tbl_rep_mon[region_id],$A4,tbl_rep_mon[year],B$3) -> 385964.7 | C4: =SUMIFS(tbl_rep_mon[flat_commission],tbl_rep_mon[region_id],$A4,tbl_rep_mon[year],C$3) -> 591914.91 | D4: =SUMIFS(tbl_rep_mon[flat_commission],tbl_rep_mon[region_id],$A4,tbl_rep_mon[year],D$3) -> 693159.35 | E4: =SUMIFS(tbl_rep_mon[flat_commission],tbl_rep_mon[region_id],$A4,tbl_rep_mon[year],E$3) -> 907089.48 | F4: =SUMIFS(tbl_rep_mon[flat_commission],tbl_rep_mon[region_id],$A4,tbl_rep_mon[year],F$3) -> 1083617 | H4: =SUM(B4:F4) -> 3661745.4
A5: 2 | B5: =SUMIFS(tbl_rep_mon[flat_commission],tbl_rep_mon[region_id],$A5,tbl_rep_mon[year],B$3) -> 614858.1 | C5: =SUMIFS(tbl_rep_mon[flat_commission],tbl_rep_mon[region_id],$A5,tbl_rep_mon[year],C$3) -> 785852.41 | D5: =SUMIFS(tbl_rep_mon[flat_commission],tbl_rep_mon[region_id],$A5,tbl_rep_mon[year],D$3) -> 979804.83 | E5: =SUMIFS(tbl_rep_mon[flat_commission],tbl_rep_mon[region_id],$A5,tbl_rep_mon[year],E$3) -> 1266689.2 | F5: =SUMIFS(tbl_rep_mon[flat_commission],tbl_rep_mon[region_id],$A5,tbl_rep_mon[year],F$3) -> 1447852.1 | H5: =SUM(B5:F5) -> 5095056.7
A6: 3 | B6: =SUMIFS(tbl_rep_mon[flat_commission],tbl_rep_mon[region_id],$A6,tbl_rep_mon[year],B$3) -> 780830.82 | C6: =SUMIFS(tbl_rep_mon[flat_commission],tbl_rep_mon[region_id],$A6,tbl_rep_mon[year],C$3) -> 821569.91 | D6: =SUMIFS(tbl_rep_mon[flat_commission],tbl_rep_mon[region_id],$A6,tbl_rep_mon[year],D$3) -> 1006310.8 | E6: =SUMIFS(tbl_rep_mon[flat_commission],tbl_rep_mon[region_id],$A6,tbl_rep_mon[year],E$3) -> 1069467.8 | F6: =SUMIFS(tbl_rep_mon[flat_commission],tbl_rep_mon[region_id],$A6,tbl_rep_mon[year],F$3) -> 1231310 | H6: =SUM(B6:F6) -> 4909489.4
A7: 4 | B7: =SUMIFS(tbl_rep_mon[flat_commission],tbl_rep_mon[region_id],$A7,tbl_rep_mon[year],B$3) -> 883656.67 | C7: =SUMIFS(tbl_rep_mon[flat_commission],tbl_rep_mon[region_id],$A7,tbl_rep_mon[year],C$3) -> 1018018.7 | D7: =SUMIFS(tbl_rep_mon[flat_commission],tbl_rep_mon[region_id],$A7,tbl_rep_mon[year],D$3) -> 1259597.2 | E7: =SUMIFS(tbl_rep_mon[flat_commission],tbl_rep_mon[region_id],$A7,tbl_rep_mon[year],E$3) -> 1499079.5 | F7: =SUMIFS(tbl_rep_mon[flat_commission],tbl_rep_mon[region_id],$A7,tbl_rep_mon[year],F$3) -> 1785206.5 | H7: =SUM(B7:F7) -> 6445558.6
A8: Company | B8: =SUM(B4:B7) -> 2665310.3 | C8: =SUM(C4:C7) -> 3217356 | D8: =SUM(D4:D7) -> 3938872.2 | E8: =SUM(E4:E7) -> 4742326 | F8: =SUM(F4:F7) -> 5547985.6 | H8: =SUM(H4:H7) -> 20111850
A10: Blended Payout Rate (flat commission/margin dollars)
B11: Year
A12: Region | B12: 2021 | C12: 2022 | D12: 2023 | E12: 2024 | F12: 2025 | H12: regional blended payout rate
A13: 1 | B13: =SUMIFS(tbl_rep_mon[flat_commission],tbl_rep_mon[region_id],$A13,tbl_rep_mon[year],B$12)/SUMIFS(tbl_rep_mon[margin_dollars],tbl_rep_mon[region_id],$A13,tbl_rep_mon[year],B$12) -> 0.46909638 | C13: =SUMIFS(tbl_rep_mon[flat_commission],tbl_rep_mon[region_id],$A13,tbl_rep_mon[year],C$12)/SUMIFS(tbl_rep_mon[margin_dollars],tbl_rep_mon[region_id],$A13,tbl_rep_mon[year],C$12) -> 0.54272471 | D13: =SUMIFS(tbl_rep_mon[flat_commission],tbl_rep_mon[region_id],$A13,tbl_rep_mon[year],D$12)/SUMIFS(tbl_rep_mon[margin_dollars],tbl_rep_mon[region_id],$A13,tbl_rep_mon[year],D$12) -> 0.56004977 | E13: =SUMIFS(tbl_rep_mon[flat_commission],tbl_rep_mon[region_id],$A13,tbl_rep_mon[year],E$12)/SUMIFS(tbl_rep_mon[margin_dollars],tbl_rep_mon[region_id],$A13,tbl_rep_mon[year],E$12) -> 0.59732484 | F13: =SUMIFS(tbl_rep_mon[flat_commission],tbl_rep_mon[region_id],$A13,tbl_rep_mon[year],F$12)/SUMIFS(tbl_rep_mon[margin_dollars],tbl_rep_mon[region_id],$A13,tbl_rep_mon[year],F$12) -> 0.6 | H13: =SUMIFS(tbl_rep_mon[flat_commission],tbl_rep_mon[region_id],$A13)/SUMIFS(tbl_rep_mon[margin_dollars],tbl_rep_mon[region_id],$A13) -> 0.56545866
A14: 2 | B14: =SUMIFS(tbl_rep_mon[flat_commission],tbl_rep_mon[region_id],$A14,tbl_rep_mon[year],B$12)/SUMIFS(tbl_rep_mon[margin_dollars],tbl_rep_mon[region_id],$A14,tbl_rep_mon[year],B$12) -> 0.397693 | C14: =SUMIFS(tbl_rep_mon[flat_commission],tbl_rep_mon[region_id],$A14,tbl_rep_mon[year],C$12)/SUMIFS(tbl_rep_mon[margin_dollars],tbl_rep_mon[region_id],$A14,tbl_rep_mon[year],C$12) -> 0.42685141 | D14: =SUMIFS(tbl_rep_mon[flat_commission],tbl_rep_mon[region_id],$A14,tbl_rep_mon[year],D$12)/SUMIFS(tbl_rep_mon[margin_dollars],tbl_rep_mon[region_id],$A14,tbl_rep_mon[year],D$12) -> 0.46400228 | E14: =SUMIFS(tbl_rep_mon[flat_commission],tbl_rep_mon[region_id],$A14,tbl_rep_mon[year],E$12)/SUMIFS(tbl_rep_mon[margin_dollars],tbl_rep_mon[region_id],$A14,tbl_rep_mon[year],E$12) -> 0.50105045 | F14: =SUMIFS(tbl_rep_mon[flat_commission],tbl_rep_mon[region_id],$A14,tbl_rep_mon[year],F$12)/SUMIFS(tbl_rep_mon[margin_dollars],tbl_rep_mon[region_id],$A14,tbl_rep_mon[year],F$12) -> 0.5340585 | H14: =SUMIFS(tbl_rep_mon[flat_commission],tbl_rep_mon[region_id],$A14)/SUMIFS(tbl_rep_mon[margin_dollars],tbl_rep_mon[region_id],$A14) -> 0.47449513
A15: 3 | B15: =SUMIFS(tbl_rep_mon[flat_commission],tbl_rep_mon[region_id],$A15,tbl_rep_mon[year],B$12)/SUMIFS(tbl_rep_mon[margin_dollars],tbl_rep_mon[region_id],$A15,tbl_rep_mon[year],B$12) -> 0.42390483 | C15: =SUMIFS(tbl_rep_mon[flat_commission],tbl_rep_mon[region_id],$A15,tbl_rep_mon[year],C$12)/SUMIFS(tbl_rep_mon[margin_dollars],tbl_rep_mon[region_id],$A15,tbl_rep_mon[year],C$12) -> 0.43583867 | D15: =SUMIFS(tbl_rep_mon[flat_commission],tbl_rep_mon[region_id],$A15,tbl_rep_mon[year],D$12)/SUMIFS(tbl_rep_mon[margin_dollars],tbl_rep_mon[region_id],$A15,tbl_rep_mon[year],D$12) -> 0.46497959 | E15: =SUMIFS(tbl_rep_mon[flat_commission],tbl_rep_mon[region_id],$A15,tbl_rep_mon[year],E$12)/SUMIFS(tbl_rep_mon[margin_dollars],tbl_rep_mon[region_id],$A15,tbl_rep_mon[year],E$12) -> 0.48280998 | F15: =SUMIFS(tbl_rep_mon[flat_commission],tbl_rep_mon[region_id],$A15,tbl_rep_mon[year],F$12)/SUMIFS(tbl_rep_mon[margin_dollars],tbl_rep_mon[region_id],$A15,tbl_rep_mon[year],F$12) -> 0.49992858 | H15: =SUMIFS(tbl_rep_mon[flat_commission],tbl_rep_mon[region_id],$A15)/SUMIFS(tbl_rep_mon[margin_dollars],tbl_rep_mon[region_id],$A15) -> 0.46450493
A16: 4 | B16: =SUMIFS(tbl_rep_mon[flat_commission],tbl_rep_mon[region_id],$A16,tbl_rep_mon[year],B$12)/SUMIFS(tbl_rep_mon[margin_dollars],tbl_rep_mon[region_id],$A16,tbl_rep_mon[year],B$12) -> 0.37450517 | C16: =SUMIFS(tbl_rep_mon[flat_commission],tbl_rep_mon[region_id],$A16,tbl_rep_mon[year],C$12)/SUMIFS(tbl_rep_mon[margin_dollars],tbl_rep_mon[region_id],$A16,tbl_rep_mon[year],C$12) -> 0.40124138 | D16: =SUMIFS(tbl_rep_mon[flat_commission],tbl_rep_mon[region_id],$A16,tbl_rep_mon[year],D$12)/SUMIFS(tbl_rep_mon[margin_dollars],tbl_rep_mon[region_id],$A16,tbl_rep_mon[year],D$12) -> 0.42265286 | E16: =SUMIFS(tbl_rep_mon[flat_commission],tbl_rep_mon[region_id],$A16,tbl_rep_mon[year],E$12)/SUMIFS(tbl_rep_mon[margin_dollars],tbl_rep_mon[region_id],$A16,tbl_rep_mon[year],E$12) -> 0.45270893 | F16: =SUMIFS(tbl_rep_mon[flat_commission],tbl_rep_mon[region_id],$A16,tbl_rep_mon[year],F$12)/SUMIFS(tbl_rep_mon[margin_dollars],tbl_rep_mon[region_id],$A16,tbl_rep_mon[year],F$12) -> 0.48363836 | H16: =SUMIFS(tbl_rep_mon[flat_commission],tbl_rep_mon[region_id],$A16)/SUMIFS(tbl_rep_mon[margin_dollars],tbl_rep_mon[region_id],$A16) -> 0.43318451
A17: Company | B17: =SUMIFS(tbl_rep_mon[flat_commission],tbl_rep_mon[year],B$12)/SUMIFS(tbl_rep_mon[margin_dollars],tbl_rep_mon[year],B$12) -> 0.40565589 | C17: =SUMIFS(tbl_rep_mon[flat_commission],tbl_rep_mon[year],C$12)/SUMIFS(tbl_rep_mon[margin_dollars],tbl_rep_mon[year],C$12) -> 0.43750425 | D17: =SUMIFS(tbl_rep_mon[flat_commission],tbl_rep_mon[year],D$12)/SUMIFS(tbl_rep_mon[margin_dollars],tbl_rep_mon[year],D$12) -> 0.4637386 | E17: =SUMIFS(tbl_rep_mon[flat_commission],tbl_rep_mon[year],E$12)/SUMIFS(tbl_rep_mon[margin_dollars],tbl_rep_mon[year],E$12) -> 0.49538048 | F17: =SUMIFS(tbl_rep_mon[flat_commission],tbl_rep_mon[year],F$12)/SUMIFS(tbl_rep_mon[margin_dollars],tbl_rep_mon[year],F$12) -> 0.51990084 | H17: =SUM(tbl_rep_mon[flat_commission])/SUM(tbl_rep_mon[margin_dollars]) -> 0.47141943

Sheet Overpay
A1: Overpay
B2: Year
A3: Region | B3: 2021 | C3: 2022 | D3: 2023 | E3: 2024 | F3: 2025 | H3: Overpay by region | J3: Total overpay
A4: 1 | B4: =SUMIFS(tbl_rep_mon[overpay],tbl_rep_mon[region_id],$A4,tbl_rep_mon[year],B$3) -> 109500 | C4: =SUMIFS(tbl_rep_mon[overpay],tbl_rep_mon[region_id],$A4,tbl_rep_mon[year],C$3) -> 188250 | D4: =SUMIFS(tbl_rep_mon[overpay],tbl_rep_mon[region_id],$A4,tbl_rep_mon[year],D$3) -> 213000 | E4: =SUMIFS(tbl_rep_mon[overpay],tbl_rep_mon[region_id],$A4,tbl_rep_mon[year],E$3) -> 262500 | F4: =SUMIFS(tbl_rep_mon[overpay],tbl_rep_mon[region_id],$A4,tbl_rep_mon[year],F$3) -> 267000 | H4: =SUM(B4:F4) -> 1040250 | J4: =SUM(B4:F7) -> 5480500
A5: 2 | B5: =SUMIFS(tbl_rep_mon[overpay],tbl_rep_mon[region_id],$A5,tbl_rep_mon[year],B$3) -> 148000 | C5: =SUMIFS(tbl_rep_mon[overpay],tbl_rep_mon[region_id],$A5,tbl_rep_mon[year],C$3) -> 204000 | D5: =SUMIFS(tbl_rep_mon[overpay],tbl_rep_mon[region_id],$A5,tbl_rep_mon[year],D$3) -> 273875 | E5: =SUMIFS(tbl_rep_mon[overpay],tbl_rep_mon[region_id],$A5,tbl_rep_mon[year],E$3) -> 366000 | F5: =SUMIFS(tbl_rep_mon[overpay],tbl_rep_mon[region_id],$A5,tbl_rep_mon[year],F$3) -> 439375 | H5: =SUM(B5:F5) -> 1431250
A6: 3 | B6: =SUMIFS(tbl_rep_mon[overpay],tbl_rep_mon[region_id],$A6,tbl_rep_mon[year],B$3) -> 195125 | C6: =SUMIFS(tbl_rep_mon[overpay],tbl_rep_mon[region_id],$A6,tbl_rep_mon[year],C$3) -> 214250 | D6: =SUMIFS(tbl_rep_mon[overpay],tbl_rep_mon[region_id],$A6,tbl_rep_mon[year],D$3) -> 277125 | E6: =SUMIFS(tbl_rep_mon[overpay],tbl_rep_mon[region_id],$A6,tbl_rep_mon[year],E$3) -> 304375 | F6: =SUMIFS(tbl_rep_mon[overpay],tbl_rep_mon[region_id],$A6,tbl_rep_mon[year],F$3) -> 358125 | H6: =SUM(B6:F6) -> 1349000
A7: 4 | B7: =SUMIFS(tbl_rep_mon[overpay],tbl_rep_mon[region_id],$A7,tbl_rep_mon[year],B$3) -> 189500 | C7: =SUMIFS(tbl_rep_mon[overpay],tbl_rep_mon[region_id],$A7,tbl_rep_mon[year],C$3) -> 242875 | D7: =SUMIFS(tbl_rep_mon[overpay],tbl_rep_mon[region_id],$A7,tbl_rep_mon[year],D$3) -> 313250 | E7: =SUMIFS(tbl_rep_mon[overpay],tbl_rep_mon[region_id],$A7,tbl_rep_mon[year],E$3) -> 406500 | F7: =SUMIFS(tbl_rep_mon[overpay],tbl_rep_mon[region_id],$A7,tbl_rep_mon[year],F$3) -> 507875 | H7: =SUM(B7:F7) -> 1660000
A8: Company | B8: =SUM(B4:B7) -> 642125 | C8: =SUM(C4:C7) -> 849375 | D8: =SUM(D4:D7) -> 1077250 | E8: =SUM(E4:E7) -> 1339375 | F8: =SUM(F4:F7) -> 1572375 | H8: =SUM(H4:H7) -> 5480500
A11: Overpay by rep month by region and year
B12: Year
A13: Region | B13: 2021 | C13: 2022 | D13: 2023 | E13: 2024 | F13: 2025
A14: 1 | B14: =SUMIFS(tbl_rep_mon[overpay],tbl_rep_mon[region_id],$A14,tbl_rep_mon[year],B$13)/COUNTIFS(tbl_rep_mon[region_id],$A14,tbl_rep_mon[year],B$13) -> 4562.5 | C14: =SUMIFS(tbl_rep_mon[overpay],tbl_rep_mon[region_id],$A14,tbl_rep_mon[year],C$13)/COUNTIFS(tbl_rep_mon[region_id],$A14,tbl_rep_mon[year],C$13) -> 7843.75 | D14: =SUMIFS(tbl_rep_mon[overpay],tbl_rep_mon[region_id],$A14,tbl_rep_mon[year],D$13)/COUNTIFS(tbl_rep_mon[region_id],$A14,tbl_rep_mon[year],D$13) -> 8875 | E14: =SUMIFS(tbl_rep_mon[overpay],tbl_rep_mon[region_id],$A14,tbl_rep_mon[year],E$13)/COUNTIFS(tbl_rep_mon[region_id],$A14,tbl_rep_mon[year],E$13) -> 10937.5 | F14: =SUMIFS(tbl_rep_mon[overpay],tbl_rep_mon[region_id],$A14,tbl_rep_mon[year],F$13)/COUNTIFS(tbl_rep_mon[region_id],$A14,tbl_rep_mon[year],F$13) -> 11125
A15: 2 | B15: =SUMIFS(tbl_rep_mon[overpay],tbl_rep_mon[region_id],$A15,tbl_rep_mon[year],B$13)/COUNTIFS(tbl_rep_mon[region_id],$A15,tbl_rep_mon[year],B$13) -> 2508.4746 | C15: =SUMIFS(tbl_rep_mon[overpay],tbl_rep_mon[region_id],$A15,tbl_rep_mon[year],C$13)/COUNTIFS(tbl_rep_mon[region_id],$A15,tbl_rep_mon[year],C$13) -> 3400 | D15: =SUMIFS(tbl_rep_mon[overpay],tbl_rep_mon[region_id],$A15,tbl_rep_mon[year],D$13)/COUNTIFS(tbl_rep_mon[region_id],$A15,tbl_rep_mon[year],D$13) -> 4564.5833 | E15: =SUMIFS(tbl_rep_mon[overpay],tbl_rep_mon[region_id],$A15,tbl_rep_mon[year],E$13)/COUNTIFS(tbl_rep_mon[region_id],$A15,tbl_rep_mon[year],E$13) -> 6000 | F15: =SUMIFS(tbl_rep_mon[overpay],tbl_rep_mon[region_id],$A15,tbl_rep_mon[year],F$13)/COUNTIFS(tbl_rep_mon[region_id],$A15,tbl_rep_mon[year],F$13) -> 7322.9167
A16: 3 | B16: =SUMIFS(tbl_rep_mon[overpay],tbl_rep_mon[region_id],$A16,tbl_rep_mon[year],B$13)/COUNTIFS(tbl_rep_mon[region_id],$A16,tbl_rep_mon[year],B$13) -> 3252.0833 | C16: =SUMIFS(tbl_rep_mon[overpay],tbl_rep_mon[region_id],$A16,tbl_rep_mon[year],C$13)/COUNTIFS(tbl_rep_mon[region_id],$A16,tbl_rep_mon[year],C$13) -> 3570.8333 | D16: =SUMIFS(tbl_rep_mon[overpay],tbl_rep_mon[region_id],$A16,tbl_rep_mon[year],D$13)/COUNTIFS(tbl_rep_mon[region_id],$A16,tbl_rep_mon[year],D$13) -> 4618.75 | E16: =SUMIFS(tbl_rep_mon[overpay],tbl_rep_mon[region_id],$A16,tbl_rep_mon[year],E$13)/COUNTIFS(tbl_rep_mon[region_id],$A16,tbl_rep_mon[year],E$13) -> 5158.8983 | F16: =SUMIFS(tbl_rep_mon[overpay],tbl_rep_mon[region_id],$A16,tbl_rep_mon[year],F$13)/COUNTIFS(tbl_rep_mon[region_id],$A16,tbl_rep_mon[year],F$13) -> 5968.75
A17: 4 | B17: =SUMIFS(tbl_rep_mon[overpay],tbl_rep_mon[region_id],$A17,tbl_rep_mon[year],B$13)/COUNTIFS(tbl_rep_mon[region_id],$A17,tbl_rep_mon[year],B$13) -> 1953.6082 | C17: =SUMIFS(tbl_rep_mon[overpay],tbl_rep_mon[region_id],$A17,tbl_rep_mon[year],C$13)/COUNTIFS(tbl_rep_mon[region_id],$A17,tbl_rep_mon[year],C$13) -> 2529.9479 | D17: =SUMIFS(tbl_rep_mon[overpay],tbl_rep_mon[region_id],$A17,tbl_rep_mon[year],D$13)/COUNTIFS(tbl_rep_mon[region_id],$A17,tbl_rep_mon[year],D$13) -> 3263.0208 | E17: =SUMIFS(tbl_rep_mon[overpay],tbl_rep_mon[region_id],$A17,tbl_rep_mon[year],E$13)/COUNTIFS(tbl_rep_mon[region_id],$A17,tbl_rep_mon[year],E$13) -> 4234.375 | F17: =SUMIFS(tbl_rep_mon[overpay],tbl_rep_mon[region_id],$A17,tbl_rep_mon[year],F$13)/COUNTIFS(tbl_rep_mon[region_id],$A17,tbl_rep_mon[year],F$13) -> 5290.3646
A18: Company | B18: =SUMIFS(tbl_rep_mon[overpay],tbl_rep_mon[year],B$13)/COUNTIFS(tbl_rep_mon[year],B$13) -> 2675.5208 | C18: =SUMIFS(tbl_rep_mon[overpay],tbl_rep_mon[year],C$13)/COUNTIFS(tbl_rep_mon[year],C$13) -> 3539.0625 | D18: =SUMIFS(tbl_rep_mon[overpay],tbl_rep_mon[year],D$13)/COUNTIFS(tbl_rep_mon[year],D$13) -> 4488.5417 | E18: =SUMIFS(tbl_rep_mon[overpay],tbl_rep_mon[year],E$13)/COUNTIFS(tbl_rep_mon[year],E$13) -> 5580.7292 | F18: =SUMIFS(tbl_rep_mon[overpay],tbl_rep_mon[year],F$13)/COUNTIFS(tbl_rep_mon[year],F$13) -> 6551.5625
A20: Average net sales per rep-month by region and year
B21: Year
A22: Region | B22: 2021 | C22: 2022 | D22: 2023 | E22: 2024 | F22: 2025
A23: 1 | B23: =AVERAGEIFS(tbl_rep_mon[net_sales],tbl_rep_mon[region_id],$A23,tbl_rep_mon[year],B$22) -> 68565.281 | C23: =AVERAGEIFS(tbl_rep_mon[net_sales],tbl_rep_mon[region_id],$A23,tbl_rep_mon[year],C$22) -> 90886.303 | D23: =AVERAGEIFS(tbl_rep_mon[net_sales],tbl_rep_mon[region_id],$A23,tbl_rep_mon[year],D$22) -> 103139.55 | E23: =AVERAGEIFS(tbl_rep_mon[net_sales],tbl_rep_mon[region_id],$A23,tbl_rep_mon[year],E$22) -> 126548.88 | F23: =AVERAGEIFS(tbl_rep_mon[net_sales],tbl_rep_mon[region_id],$A23,tbl_rep_mon[year],F$22) -> 150502.36
A24: 2 | B24: =AVERAGEIFS(tbl_rep_mon[net_sales],tbl_rep_mon[region_id],$A24,tbl_rep_mon[year],B$22) -> 52408.887 | C24: =AVERAGEIFS(tbl_rep_mon[net_sales],tbl_rep_mon[region_id],$A24,tbl_rep_mon[year],C$22) -> 61368.148 | D24: =AVERAGEIFS(tbl_rep_mon[net_sales],tbl_rep_mon[region_id],$A24,tbl_rep_mon[year],D$22) -> 70387.933 | E24: =AVERAGEIFS(tbl_rep_mon[net_sales],tbl_rep_mon[region_id],$A24,tbl_rep_mon[year],E$22) -> 82887.449 | F24: =AVERAGEIFS(tbl_rep_mon[net_sales],tbl_rep_mon[region_id],$A24,tbl_rep_mon[year],F$22) -> 90367.887
A25: 3 | B25: =AVERAGEIFS(tbl_rep_mon[net_sales],tbl_rep_mon[region_id],$A25,tbl_rep_mon[year],B$22) -> 61399.852 | C25: =AVERAGEIFS(tbl_rep_mon[net_sales],tbl_rep_mon[region_id],$A25,tbl_rep_mon[year],C$22) -> 62834.406 | D25: =AVERAGEIFS(tbl_rep_mon[net_sales],tbl_rep_mon[region_id],$A25,tbl_rep_mon[year],D$22) -> 72140.143 | E25: =AVERAGEIFS(tbl_rep_mon[net_sales],tbl_rep_mon[region_id],$A25,tbl_rep_mon[year],E$22) -> 75087.815 | F25: =AVERAGEIFS(tbl_rep_mon[net_sales],tbl_rep_mon[region_id],$A25,tbl_rep_mon[year],F$22) -> 82099.059
A26: 4 | B26: =AVERAGEIFS(tbl_rep_mon[net_sales],tbl_rep_mon[region_id],$A26,tbl_rep_mon[year],B$22) -> 48650.13 | C26: =AVERAGEIFS(tbl_rep_mon[net_sales],tbl_rep_mon[region_id],$A26,tbl_rep_mon[year],C$22) -> 52857.767 | D26: =AVERAGEIFS(tbl_rep_mon[net_sales],tbl_rep_mon[region_id],$A26,tbl_rep_mon[year],D$22) -> 62087.853 | E26: =AVERAGEIFS(tbl_rep_mon[net_sales],tbl_rep_mon[region_id],$A26,tbl_rep_mon[year],E$22) -> 68986.539 | F26: =AVERAGEIFS(tbl_rep_mon[net_sales],tbl_rep_mon[region_id],$A26,tbl_rep_mon[year],F$22) -> 76900.026
A27: Company | B27: =AVERAGEIFS(tbl_rep_mon[net_sales],tbl_rep_mon[year],B$22) -> 54753.103 | C27: =AVERAGEIFS(tbl_rep_mon[net_sales],tbl_rep_mon[year],C$22) -> 61282.376 | D27: =AVERAGEIFS(tbl_rep_mon[net_sales],tbl_rep_mon[year],D$22) -> 70781.115 | E27: =AVERAGEIFS(tbl_rep_mon[net_sales],tbl_rep_mon[year],E$22) -> 79775.818 | F27: =AVERAGEIFS(tbl_rep_mon[net_sales],tbl_rep_mon[year],F$22) -> 88926.983
A29: Share of rep-months in the top commission tier by region and year
B30: Year
A31: Region | B31: 2021 | C31: 2022 | D31: 2023 | E31: 2024 | F31: 2025
A32: 1 | B32: =COUNTIFS(tbl_rep_mon[region_id],$A32,tbl_rep_mon[year],B$31,tbl_rep_mon[net_sales],">="&MAX(tier_floor))/COUNTIFS(tbl_rep_mon[region_id],$A32,tbl_rep_mon[year],B$31) -> 0.083333333 | C32: =COUNTIFS(tbl_rep_mon[region_id],$A32,tbl_rep_mon[year],C$31,tbl_rep_mon[net_sales],">="&MAX(tier_floor))/COUNTIFS(tbl_rep_mon[region_id],$A32,tbl_rep_mon[year],C$31) -> 0.41666667 | D32: =COUNTIFS(tbl_rep_mon[region_id],$A32,tbl_rep_mon[year],D$31,tbl_rep_mon[net_sales],">="&MAX(tier_floor))/COUNTIFS(tbl_rep_mon[region_id],$A32,tbl_rep_mon[year],D$31) -> 0.5 | E32: =COUNTIFS(tbl_rep_mon[region_id],$A32,tbl_rep_mon[year],E$31,tbl_rep_mon[net_sales],">="&MAX(tier_floor))/COUNTIFS(tbl_rep_mon[region_id],$A32,tbl_rep_mon[year],E$31) -> 0.95833333 | F32: =COUNTIFS(tbl_rep_mon[region_id],$A32,tbl_rep_mon[year],F$31,tbl_rep_mon[net_sales],">="&MAX(tier_floor))/COUNTIFS(tbl_rep_mon[region_id],$A32,tbl_rep_mon[year],F$31) -> 1
A33: 2 | B33: =COUNTIFS(tbl_rep_mon[region_id],$A33,tbl_rep_mon[year],B$31,tbl_rep_mon[net_sales],">="&MAX(tier_floor))/COUNTIFS(tbl_rep_mon[region_id],$A33,tbl_rep_mon[year],B$31) -> 0 | C33: =COUNTIFS(tbl_rep_mon[region_id],$A33,tbl_rep_mon[year],C$31,tbl_rep_mon[net_sales],">="&MAX(tier_floor))/COUNTIFS(tbl_rep_mon[region_id],$A33,tbl_rep_mon[year],C$31) -> 0 | D33: =COUNTIFS(tbl_rep_mon[region_id],$A33,tbl_rep_mon[year],D$31,tbl_rep_mon[net_sales],">="&MAX(tier_floor))/COUNTIFS(tbl_rep_mon[region_id],$A33,tbl_rep_mon[year],D$31) -> 0.016666667 | E33: =COUNTIFS(tbl_rep_mon[region_id],$A33,tbl_rep_mon[year],E$31,tbl_rep_mon[net_sales],">="&MAX(tier_floor))/COUNTIFS(tbl_rep_mon[region_id],$A33,tbl_rep_mon[year],E$31) -> 0.1147541 | F33: =COUNTIFS(tbl_rep_mon[region_id],$A33,tbl_rep_mon[year],F$31,tbl_rep_mon[net_sales],">="&MAX(tier_floor))/COUNTIFS(tbl_rep_mon[region_id],$A33,tbl_rep_mon[year],F$31) -> 0.3
A34: 3 | B34: =COUNTIFS(tbl_rep_mon[region_id],$A34,tbl_rep_mon[year],B$31,tbl_rep_mon[net_sales],">="&MAX(tier_floor))/COUNTIFS(tbl_rep_mon[region_id],$A34,tbl_rep_mon[year],B$31) -> 0 | C34: =COUNTIFS(tbl_rep_mon[region_id],$A34,tbl_rep_mon[year],C$31,tbl_rep_mon[net_sales],">="&MAX(tier_floor))/COUNTIFS(tbl_rep_mon[region_id],$A34,tbl_rep_mon[year],C$31) -> 0 | D34: =COUNTIFS(tbl_rep_mon[region_id],$A34,tbl_rep_mon[year],D$31,tbl_rep_mon[net_sales],">="&MAX(tier_floor))/COUNTIFS(tbl_rep_mon[region_id],$A34,tbl_rep_mon[year],D$31) -> 0.033333333 | E34: =COUNTIFS(tbl_rep_mon[region_id],$A34,tbl_rep_mon[year],E$31,tbl_rep_mon[net_sales],">="&MAX(tier_floor))/COUNTIFS(tbl_rep_mon[region_id],$A34,tbl_rep_mon[year],E$31) -> 0.10169492 | F34: =COUNTIFS(tbl_rep_mon[region_id],$A34,tbl_rep_mon[year],F$31,tbl_rep_mon[net_sales],">="&MAX(tier_floor))/COUNTIFS(tbl_rep_mon[region_id],$A34,tbl_rep_mon[year],F$31) -> 0.15
A35: 4 | B35: =COUNTIFS(tbl_rep_mon[region_id],$A35,tbl_rep_mon[year],B$31,tbl_rep_mon[net_sales],">="&MAX(tier_floor))/COUNTIFS(tbl_rep_mon[region_id],$A35,tbl_rep_mon[year],B$31) -> 0 | C35: =COUNTIFS(tbl_rep_mon[region_id],$A35,tbl_rep_mon[year],C$31,tbl_rep_mon[net_sales],">="&MAX(tier_floor))/COUNTIFS(tbl_rep_mon[region_id],$A35,tbl_rep_mon[year],C$31) -> 0 | D35: =COUNTIFS(tbl_rep_mon[region_id],$A35,tbl_rep_mon[year],D$31,tbl_rep_mon[net_sales],">="&MAX(tier_floor))/COUNTIFS(tbl_rep_mon[region_id],$A35,tbl_rep_mon[year],D$31) -> 0 | E35: =COUNTIFS(tbl_rep_mon[region_id],$A35,tbl_rep_mon[year],E$31,tbl_rep_mon[net_sales],">="&MAX(tier_floor))/COUNTIFS(tbl_rep_mon[region_id],$A35,tbl_rep_mon[year],E$31) -> 0.010416667 | F35: =COUNTIFS(tbl_rep_mon[region_id],$A35,tbl_rep_mon[year],F$31,tbl_rep_mon[net_sales],">="&MAX(tier_floor))/COUNTIFS(tbl_rep_mon[region_id],$A35,tbl_rep_mon[year],F$31) -> 0.0625
A36: Company | B36: =COUNTIFS(tbl_rep_mon[year],B$31,tbl_rep_mon[net_sales],">="&MAX(tier_floor))/COUNTIFS(tbl_rep_mon[year],B$31) -> 0.0083333333 | C36: =COUNTIFS(tbl_rep_mon[year],C$31,tbl_rep_mon[net_sales],">="&MAX(tier_floor))/COUNTIFS(tbl_rep_mon[year],C$31) -> 0.041666667 | D36: =COUNTIFS(tbl_rep_mon[year],D$31,tbl_rep_mon[net_sales],">="&MAX(tier_floor))/COUNTIFS(tbl_rep_mon[year],D$31) -> 0.0625 | E36: =COUNTIFS(tbl_rep_mon[year],E$31,tbl_rep_mon[net_sales],">="&MAX(tier_floor))/COUNTIFS(tbl_rep_mon[year],E$31) -> 0.15416667 | F36: =COUNTIFS(tbl_rep_mon[year],F$31,tbl_rep_mon[net_sales],">="&MAX(tier_floor))/COUNTIFS(tbl_rep_mon[year],F$31) -> 0.2375

Sheet Quota
B1: Net Sales by Region Month | H1: Quota by Region Month | N1: Attainment by Region Month | U1: Attainment by Region Year
C2: Regions | I2: Regions | O2: Regions | V2: Regions | Z2: Company
A3: Year | B3: Month | C3: 1 | D3: 2 | E3: 3 | F3: 4 | H3: Month | I3: 1 | J3: 2 | K3: 3 | L3: 4 | N3: Month | O3: 1 | P3: 2 | Q3: 3 | R3: 4 | S3: Company | U3: Year | V3: 1 | W3: 2 | X3: 3 | Y3: 4
A4: =(YEAR($B4)) -> 2021 | B4: 44197 | C4: =SUMIFS(tbl_rep_mon[net_sales],tbl_rep_mon[region_id],C$3,tbl_rep_mon[month_start],$B4) -> 138252.38 | D4: =SUMIFS(tbl_rep_mon[net_sales],tbl_rep_mon[region_id],D$3,tbl_rep_mon[month_start],$B4) -> 244213.7 | E4: =SUMIFS(tbl_rep_mon[net_sales],tbl_rep_mon[region_id],E$3,tbl_rep_mon[month_start],$B4) -> 281613.84 | F4: =SUMIFS(tbl_rep_mon[net_sales],tbl_rep_mon[region_id],F$3,tbl_rep_mon[month_start],$B4) -> 375096.13 | H4: =$B4 -> 44197 | I4: =IFERROR(_xlfn.XLOOKUP(EDATE($B4,-12),$B$4:$B$63,C$4:C$63)*(1+target),_xlfn.XLOOKUP(I$3,region,seeding)) -> 150000 | J4: =IFERROR(_xlfn.XLOOKUP(EDATE($B4,-12),$B$4:$B$63,D$4:D$63)*(1+target),_xlfn.XLOOKUP(J$3,region,seeding)) -> 275000 | K4: =IFERROR(_xlfn.XLOOKUP(EDATE($B4,-12),$B$4:$B$63,E$4:E$63)*(1+target),_xlfn.XLOOKUP(K$3,region,seeding)) -> 300000 | L4: =IFERROR(_xlfn.XLOOKUP(EDATE($B4,-12),$B$4:$B$63,F$4:F$63)*(1+target),_xlfn.XLOOKUP(L$3,region,seeding)) -> 400000 | N4: =$B4 -> 44197 | O4: =C4/I4 -> 0.92168253 | P4: =D4/J4 -> 0.88804982 | Q4: =E4/K4 -> 0.9387128 | R4: =F4/L4 -> 0.93774033 | S4: =SUM(C4:F4)/SUM(I4:L4) -> 0.92371204 | U4: 2021 | V4: =SUMIFS($C$4:$C$63,$A$4:$A$63,$U4)/SUMIFS($I$4:$I$63,$A$4:$A$63,$U4) -> 0.91420374 | W4: =SUMIFS($D$4:$D$63,$A$4:$A$63,$U4)/SUMIFS($J$4:$J$63,$A$4:$A$63,$U4) -> 0.93700737 | X4: =SUMIFS($E$4:$E$63,$A$4:$A$63,$U4)/SUMIFS($K$4:$K$63,$A$4:$A$63,$U4) -> 1.0233309 | Y4: =SUMIFS($F$4:$F$63,$A$4:$A$63,$U4)/SUMIFS($L$4:$L$63,$A$4:$A$63,$U4) -> 0.98313805 | Z4: =(SUMIF($A$4:$A$63,$U4,$C$4:$C$63)+SUMIF($A$4:$A$63,$U4,$D$4:$D$63)+SUMIF($A$4:$A$63,$U4,$E$4:$E$63)+SUMIF($A$4:$A$63,$U4,$F$4:$F$63))/(SUMIF($A$4:$A$63,$U4,$I$4:$I$63)+SUMIF($A$4:$A$63,$U4,$J$4:$J$63)+SUMIF($A$4:$A$63,$U4,$K$4:$K$63)+SUMIF($A$4:$A$63,$U4,$L$4:$L$63)) -> 0.9733885
A5: =(YEAR($B5)) -> 2021 | B5: =EDATE($B4,1) -> 44228 | C5: =SUMIFS(tbl_rep_mon[net_sales],tbl_rep_mon[region_id],C$3,tbl_rep_mon[month_start],$B5) -> 141443.56 | D5: =SUMIFS(tbl_rep_mon[net_sales],tbl_rep_mon[region_id],D$3,tbl_rep_mon[month_start],$B5) -> 244328.9 | E5: =SUMIFS(tbl_rep_mon[net_sales],tbl_rep_mon[region_id],E$3,tbl_rep_mon[month_start],$B5) -> 311864.63 | F5: =SUMIFS(tbl_rep_mon[net_sales],tbl_rep_mon[region_id],F$3,tbl_rep_mon[month_start],$B5) -> 368092.59 | H5: =$B5 -> 44228 | I5: =IFERROR(_xlfn.XLOOKUP(EDATE($B5,-12),$B$4:$B$63,C$4:C$63)*(1+target),_xlfn.XLOOKUP(I$3,region,seeding)) -> 150000 | J5: =IFERROR(_xlfn.XLOOKUP(EDATE($B5,-12),$B$4:$B$63,D$4:D$63)*(1+target),_xlfn.XLOOKUP(J$3,region,seeding)) -> 275000 | K5: =IFERROR(_xlfn.XLOOKUP(EDATE($B5,-12),$B$4:$B$63,E$4:E$63)*(1+target),_xlfn.XLOOKUP(K$3,region,seeding)) -> 300000 | L5: =IFERROR(_xlfn.XLOOKUP(EDATE($B5,-12),$B$4:$B$63,F$4:F$63)*(1+target),_xlfn.XLOOKUP(L$3,region,seeding)) -> 400000 | N5: =$B5 -> 44228 | O5: =C5/I5 -> 0.94295707 | P5: =D5/J5 -> 0.88846873 | Q5: =E5/K5 -> 1.0395488 | R5: =F5/L5 -> 0.92023147 | S5: =SUM(C5:F5)/SUM(I5:L5) -> 0.94731527 | U5: 2022 | V5: =SUMIFS($C$4:$C$63,$A$4:$A$63,$U5)/SUMIFS($I$4:$I$63,$A$4:$A$63,$U5) -> 1.152647 | W5: =SUMIFS($D$4:$D$63,$A$4:$A$63,$U5)/SUMIFS($J$4:$J$63,$A$4:$A$63,$U5) -> 1.0354747 | X5: =SUMIFS($E$4:$E$63,$A$4:$A$63,$U5)/SUMIFS($K$4:$K$63,$A$4:$A$63,$U5) -> 0.88988186 | Y5: =SUMIFS($F$4:$F$63,$A$4:$A$63,$U5)/SUMIFS($L$4:$L$63,$A$4:$A$63,$U5) -> 0.93503198 | Z5: =(SUMIF($A$4:$A$63,$U5,$C$4:$C$63)+SUMIF($A$4:$A$63,$U5,$D$4:$D$63)+SUMIF($A$4:$A$63,$U5,$E$4:$E$63)+SUMIF($A$4:$A$63,$U5,$F$4:$F$63))/(SUMIF($A$4:$A$63,$U5,$I$4:$I$63)+SUMIF($A$4:$A$63,$U5,$J$4:$J$63)+SUMIF($A$4:$A$63,$U5,$K$4:$K$63)+SUMIF($A$4:$A$63,$U5,$L$4:$L$63)) -> 0.97326031
A6: =(YEAR($B6)) -> 2021 | B6: =EDATE($B5,1) -> 44256 | C6: =SUMIFS(tbl_rep_mon[net_sales],tbl_rep_mon[region_id],C$3,tbl_rep_mon[month_start],$B6) -> 147263.38 | D6: =SUMIFS(tbl_rep_mon[net_sales],tbl_rep_mon[region_id],D$3,tbl_rep_mon[month_start],$B6) -> 251196.84 | E6: =SUMIFS(tbl_rep_mon[net_sales],tbl_rep_mon[region_id],E$3,tbl_rep_mon[month_start],$B6) -> 327068.87 | F6: =SUMIFS(tbl_rep_mon[net_sales],tbl_rep_mon[region_id],F$3,tbl_rep_mon[month_start],$B6) -> 386945.19 | H6: =$B6 -> 44256 | I6: =IFERROR(_xlfn.XLOOKUP(EDATE($B6,-12),$B$4:$B$63,C$4:C$63)*(1+target),_xlfn.XLOOKUP(I$3,region,seeding)) -> 150000 | J6: =IFERROR(_xlfn.XLOOKUP(EDATE($B6,-12),$B$4:$B$63,D$4:D$63)*(1+target),_xlfn.XLOOKUP(J$3,region,seeding)) -> 275000 | K6: =IFERROR(_xlfn.XLOOKUP(EDATE($B6,-12),$B$4:$B$63,E$4:E$63)*(1+target),_xlfn.XLOOKUP(K$3,region,seeding)) -> 300000 | L6: =IFERROR(_xlfn.XLOOKUP(EDATE($B6,-12),$B$4:$B$63,F$4:F$63)*(1+target),_xlfn.XLOOKUP(L$3,region,seeding)) -> 400000 | N6: =$B6 -> 44256 | O6: =C6/I6 -> 0.98175587 | P6: =D6/J6 -> 0.91344305 | Q6: =E6/K6 -> 1.0902296 | R6: =F6/L6 -> 0.96736298 | S6: =SUM(C6:F6)/SUM(I6:L6) -> 0.98886603 | U6: 2023 | V6: =SUMIFS($C$4:$C$63,$A$4:$A$63,$U6)/SUMIFS($I$4:$I$63,$A$4:$A$63,$U6) -> 0.98679954 | W6: =SUMIFS($D$4:$D$63,$A$4:$A$63,$U6)/SUMIFS($J$4:$J$63,$A$4:$A$63,$U6) -> 0.99737242 | X6: =SUMIFS($E$4:$E$63,$A$4:$A$63,$U6)/SUMIFS($K$4:$K$63,$A$4:$A$63,$U6) -> 0.99834729 | Y6: =SUMIFS($F$4:$F$63,$A$4:$A$63,$U6)/SUMIFS($L$4:$L$63,$A$4:$A$63,$U6) -> 1.0214097 | Z6: =(SUMIF($A$4:$A$63,$U6,$C$4:$C$63)+SUMIF($A$4:$A$63,$U6,$D$4:$D$63)+SUMIF($A$4:$A$63,$U6,$E$4:$E$63)+SUMIF($A$4:$A$63,$U6,$F$4:$F$63))/(SUMIF($A$4:$A$63,$U6,$I$4:$I$63)+SUMIF($A$4:$A$63,$U6,$J$4:$J$63)+SUMIF($A$4:$A$63,$U6,$K$4:$K$63)+SUMIF($A$4:$A$63,$U6,$L$4:$L$63)) -> 1.0043474
A7: =(YEAR($B7)) -> 2021 | B7: =EDATE($B6,1) -> 44287 | C7: =SUMIFS(tbl_rep_mon[net_sales],tbl_rep_mon[region_id],C$3,tbl_rep_mon[month_start],$B7) -> 129495.45 | D7: =SUMIFS(tbl_rep_mon[net_sales],tbl_rep_mon[region_id],D$3,tbl_rep_mon[month_start],$B7) -> 242796.98 | E7: =SUMIFS(tbl_rep_mon[net_sales],tbl_rep_mon[region_id],E$3,tbl_rep_mon[month_start],$B7) -> 301087.98 | F7: =SUMIFS(tbl_rep_mon[net_sales],tbl_rep_mon[region_id],F$3,tbl_rep_mon[month_start],$B7) -> 404903.09 | H7: =$B7 -> 44287 | I7: =IFERROR(_xlfn.XLOOKUP(EDATE($B7,-12),$B$4:$B$63,C$4:C$63)*(1+target),_xlfn.XLOOKUP(I$3,region,seeding)) -> 150000 | J7: =IFERROR(_xlfn.XLOOKUP(EDATE($B7,-12),$B$4:$B$63,D$4:D$63)*(1+target),_xlfn.XLOOKUP(J$3,region,seeding)) -> 275000 | K7: =IFERROR(_xlfn.XLOOKUP(EDATE($B7,-12),$B$4:$B$63,E$4:E$63)*(1+target),_xlfn.XLOOKUP(K$3,region,seeding)) -> 300000 | L7: =IFERROR(_xlfn.XLOOKUP(EDATE($B7,-12),$B$4:$B$63,F$4:F$63)*(1+target),_xlfn.XLOOKUP(L$3,region,seeding)) -> 400000 | N7: =$B7 -> 44287 | O7: =C7/I7 -> 0.863303 | P7: =D7/J7 -> 0.88289811 | Q7: =E7/K7 -> 1.0036266 | R7: =F7/L7 -> 1.0122577 | S7: =SUM(C7:F7)/SUM(I7:L7) -> 0.95847422 | U7: 2024 | V7: =SUMIFS($C$4:$C$63,$A$4:$A$63,$U7)/SUMIFS($I$4:$I$63,$A$4:$A$63,$U7) -> 1.0669283 | W7: =SUMIFS($D$4:$D$63,$A$4:$A$63,$U7)/SUMIFS($J$4:$J$63,$A$4:$A$63,$U7) -> 1.0410493 | X7: =SUMIFS($E$4:$E$63,$A$4:$A$63,$U7)/SUMIFS($K$4:$K$63,$A$4:$A$63,$U7) -> 0.89001102 | Y7: =SUMIFS($F$4:$F$63,$A$4:$A$63,$U7)/SUMIFS($L$4:$L$63,$A$4:$A$63,$U7) -> 0.96618407 | Z7: =(SUMIF($A$4:$A$63,$U7,$C$4:$C$63)+SUMIF($A$4:$A$63,$U7,$D$4:$D$63)+SUMIF($A$4:$A$63,$U7,$E$4:$E$63)+SUMIF($A$4:$A$63,$U7,$F$4:$F$63))/(SUMIF($A$4:$A$63,$U7,$I$4:$I$63)+SUMIF($A$4:$A$63,$U7,$J$4:$J$63)+SUMIF($A$4:$A$63,$U7,$K$4:$K$63)+SUMIF($A$4:$A$63,$U7,$L$4:$L$63)) -> 0.98006759
A8: =(YEAR($B8)) -> 2021 | B8: =EDATE($B7,1) -> 44317 | C8: =SUMIFS(tbl_rep_mon[net_sales],tbl_rep_mon[region_id],C$3,tbl_rep_mon[month_start],$B8) -> 166759.13 | D8: =SUMIFS(tbl_rep_mon[net_sales],tbl_rep_mon[region_id],D$3,tbl_rep_mon[month_start],$B8) -> 229561.95 | E8: =SUMIFS(tbl_rep_mon[net_sales],tbl_rep_mon[region_id],E$3,tbl_rep_mon[month_start],$B8) -> 343548.95 | F8: =SUMIFS(tbl_rep_mon[net_sales],tbl_rep_mon[region_id],F$3,tbl_rep_mon[month_start],$B8) -> 421137.53 | H8: =$B8 -> 44317 | I8: =IFERROR(_xlfn.XLOOKUP(EDATE($B8,-12),$B$4:$B$63,C$4:C$63)*(1+target),_xlfn.XLOOKUP(I$3,region,seeding)) -> 150000 | J8: =IFERROR(_xlfn.XLOOKUP(EDATE($B8,-12),$B$4:$B$63,D$4:D$63)*(1+target),_xlfn.XLOOKUP(J$3,region,seeding)) -> 275000 | K8: =IFERROR(_xlfn.XLOOKUP(EDATE($B8,-12),$B$4:$B$63,E$4:E$63)*(1+target),_xlfn.XLOOKUP(K$3,region,seeding)) -> 300000 | L8: =IFERROR(_xlfn.XLOOKUP(EDATE($B8,-12),$B$4:$B$63,F$4:F$63)*(1+target),_xlfn.XLOOKUP(L$3,region,seeding)) -> 400000 | N8: =$B8 -> 44317 | O8: =C8/I8 -> 1.1117275 | P8: =D8/J8 -> 0.83477073 | Q8: =E8/K8 -> 1.1451632 | R8: =F8/L8 -> 1.0528438 | S8: =SUM(C8:F8)/SUM(I8:L8) -> 1.0320067 | U8: 2025 | V8: =SUMIFS($C$4:$C$63,$A$4:$A$63,$U8)/SUMIFS($I$4:$I$63,$A$4:$A$63,$U8) -> 1.0341586 | W8: =SUMIFS($D$4:$D$63,$A$4:$A$63,$U8)/SUMIFS($J$4:$J$63,$A$4:$A$63,$U8) -> 0.93250018 | X8: =SUMIFS($E$4:$E$63,$A$4:$A$63,$U8)/SUMIFS($K$4:$K$63,$A$4:$A$63,$U8) -> 0.96687452 | Y8: =SUMIFS($F$4:$F$63,$A$4:$A$63,$U8)/SUMIFS($L$4:$L$63,$A$4:$A$63,$U8) -> 0.96931357 | Z8: =(SUMIF($A$4:$A$63,$U8,$C$4:$C$63)+SUMIF($A$4:$A$63,$U8,$D$4:$D$63)+SUMIF($A$4:$A$63,$U8,$E$4:$E$63)+SUMIF($A$4:$A$63,$U8,$F$4:$F$63))/(SUMIF($A$4:$A$63,$U8,$I$4:$I$63)+SUMIF($A$4:$A$63,$U8,$J$4:$J$63)+SUMIF($A$4:$A$63,$U8,$K$4:$K$63)+SUMIF($A$4:$A$63,$U8,$L$4:$L$63)) -> 0.96931392
A9: =(YEAR($B9)) -> 2021 | B9: =EDATE($B8,1) -> 44348 | C9: =SUMIFS(tbl_rep_mon[net_sales],tbl_rep_mon[region_id],C$3,tbl_rep_mon[month_start],$B9) -> 162630.92 | D9: =SUMIFS(tbl_rep_mon[net_sales],tbl_rep_mon[region_id],D$3,tbl_rep_mon[month_start],$B9) -> 282876.73 | E9: =SUMIFS(tbl_rep_mon[net_sales],tbl_rep_mon[region_id],E$3,tbl_rep_mon[month_start],$B9) -> 309608.34 | F9: =SUMIFS(tbl_rep_mon[net_sales],tbl_rep_mon[region_id],F$3,tbl_rep_mon[month_start],$B9) -> 468874.7 | H9: =$B9 -> 44348 | I9: =IFERROR(_xlfn.XLOOKUP(EDATE($B9,-12),$B$4:$B$63,C$4:C$63)*(1+target),_xlfn.XLOOKUP(I$3,region,seeding)) -> 150000 | J9: =IFERROR(_xlfn.XLOOKUP(EDATE($B9,-12),$B$4:$B$63,D$4:D$63)*(1+target),_xlfn.XLOOKUP(J$3,region,seeding)) -> 275000 | K9: =IFERROR(_xlfn.XLOOKUP(EDATE($B9,-12),$B$4:$B$63,E$4:E$63)*(1+target),_xlfn.XLOOKUP(K$3,region,seeding)) -> 300000 | L9: =IFERROR(_xlfn.XLOOKUP(EDATE($B9,-12),$B$4:$B$63,F$4:F$63)*(1+target),_xlfn.XLOOKUP(L$3,region,seeding)) -> 400000 | N9: =$B9 -> 44348 | O9: =C9/I9 -> 1.0842061 | P9: =D9/J9 -> 1.0286427 | Q9: =E9/K9 -> 1.0320278 | R9: =F9/L9 -> 1.1721867 | S9: =SUM(C9:F9)/SUM(I9:L9) -> 1.0879917
A10: =(YEAR($B10)) -> 2021 | B10: =EDATE($B9,1) -> 44378 | C10: =SUMIFS(tbl_rep_mon[net_sales],tbl_rep_mon[region_id],C$3,tbl_rep_mon[month_start],$B10) -> 118022 | D10: =SUMIFS(tbl_rep_mon[net_sales],tbl_rep_mon[region_id],D$3,tbl_rep_mon[month_start],$B10) -> 307125.63 | E10: =SUMIFS(tbl_rep_mon[net_sales],tbl_rep_mon[region_id],E$3,tbl_rep_mon[month_start],$B10) -> 331691.46 | F10: =SUMIFS(tbl_rep_mon[net_sales],tbl_rep_mon[region_id],F$3,tbl_rep_mon[month_start],$B10) -> 423938.31 | H10: =$B10 -> 44378 | I10: =IFERROR(_xlfn.XLOOKUP(EDATE($B10,-12),$B$4:$B$63,C$4:C$63)*(1+target),_xlfn.XLOOKUP(I$3,region,seeding)) -> 150000 | J10: =IFERROR(_xlfn.XLOOKUP(EDATE($B10,-12),$B$4:$B$63,D$4:D$63)*(1+target),_xlfn.XLOOKUP(J$3,region,seeding)) -> 275000 | K10: =IFERROR(_xlfn.XLOOKUP(EDATE($B10,-12),$B$4:$B$63,E$4:E$63)*(1+target),_xlfn.XLOOKUP(K$3,region,seeding)) -> 300000 | L10: =IFERROR(_xlfn.XLOOKUP(EDATE($B10,-12),$B$4:$B$63,F$4:F$63)*(1+target),_xlfn.XLOOKUP(L$3,region,seeding)) -> 400000 | N10: =$B10 -> 44378 | O10: =C10/I10 -> 0.78681333 | P10: =D10/J10 -> 1.1168205 | Q10: =E10/K10 -> 1.1056382 | R10: =F10/L10 -> 1.0598458 | S10: =SUM(C10:F10)/SUM(I10:L10) -> 1.0495799
A11: =(YEAR($B11)) -> 2021 | B11: =EDATE($B10,1) -> 44409 | C11: =SUMIFS(tbl_rep_mon[net_sales],tbl_rep_mon[region_id],C$3,tbl_rep_mon[month_start],$B11) -> 134309.01 | D11: =SUMIFS(tbl_rep_mon[net_sales],tbl_rep_mon[region_id],D$3,tbl_rep_mon[month_start],$B11) -> 278785.88 | E11: =SUMIFS(tbl_rep_mon[net_sales],tbl_rep_mon[region_id],E$3,tbl_rep_mon[month_start],$B11) -> 316787.55 | F11: =SUMIFS(tbl_rep_mon[net_sales],tbl_rep_mon[region_id],F$3,tbl_rep_mon[month_start],$B11) -> 375339.36 | H11: =$B11 -> 44409 | I11: =IFERROR(_xlfn.XLOOKUP(EDATE($B11,-12),$B$4:$B$63,C$4:C$63)*(1+target),_xlfn.XLOOKUP(I$3,region,seeding)) -> 150000 | J11: =IFERROR(_xlfn.XLOOKUP(EDATE($B11,-12),$B$4:$B$63,D$4:D$63)*(1+target),_xlfn.XLOOKUP(J$3,region,seeding)) -> 275000 | K11: =IFERROR(_xlfn.XLOOKUP(EDATE($B11,-12),$B$4:$B$63,E$4:E$63)*(1+target),_xlfn.XLOOKUP(K$3,region,seeding)) -> 300000 | L11: =IFERROR(_xlfn.XLOOKUP(EDATE($B11,-12),$B$4:$B$63,F$4:F$63)*(1+target),_xlfn.XLOOKUP(L$3,region,seeding)) -> 400000 | N11: =$B11 -> 44409 | O11: =C11/I11 -> 0.8953934 | P11: =D11/J11 -> 1.0137668 | Q11: =E11/K11 -> 1.0559585 | R11: =F11/L11 -> 0.9383484 | S11: =SUM(C11:F11)/SUM(I11:L11) -> 0.98241938
A12: =(YEAR($B12)) -> 2021 | B12: =EDATE($B11,1) -> 44440 | C12: =SUMIFS(tbl_rep_mon[net_sales],tbl_rep_mon[region_id],C$3,tbl_rep_mon[month_start],$B12) -> 133060.46 | D12: =SUMIFS(tbl_rep_mon[net_sales],tbl_rep_mon[region_id],D$3,tbl_rep_mon[month_start],$B12) -> 299839.9 | E12: =SUMIFS(tbl_rep_mon[net_sales],tbl_rep_mon[region_id],E$3,tbl_rep_mon[month_start],$B12) -> 317122.93 | F12: =SUMIFS(tbl_rep_mon[net_sales],tbl_rep_mon[region_id],F$3,tbl_rep_mon[month_start],$B12) -> 386346.71 | H12: =$B12 -> 44440 | I12: =IFERROR(_xlfn.XLOOKUP(EDATE($B12,-12),$B$4:$B$63,C$4:C$63)*(1+target),_xlfn.XLOOKUP(I$3,region,seeding)) -> 150000 | J12: =IFERROR(_xlfn.XLOOKUP(EDATE($B12,-12),$B$4:$B$63,D$4:D$63)*(1+target),_xlfn.XLOOKUP(J$3,region,seeding)) -> 275000 | K12: =IFERROR(_xlfn.XLOOKUP(EDATE($B12,-12),$B$4:$B$63,E$4:E$63)*(1+target),_xlfn.XLOOKUP(K$3,region,seeding)) -> 300000 | L12: =IFERROR(_xlfn.XLOOKUP(EDATE($B12,-12),$B$4:$B$63,F$4:F$63)*(1+target),_xlfn.XLOOKUP(L$3,region,seeding)) -> 400000 | N12: =$B12 -> 44440 | O12: =C12/I12 -> 0.88706973 | P12: =D12/J12 -> 1.0903269 | Q12: =E12/K12 -> 1.0570764 | R12: =F12/L12 -> 0.96586677 | S12: =SUM(C12:F12)/SUM(I12:L12) -> 1.0101067
A13: =(YEAR($B13)) -> 2021 | B13: =EDATE($B12,1) -> 44470 | C13: =SUMIFS(tbl_rep_mon[net_sales],tbl_rep_mon[region_id],C$3,tbl_rep_mon[month_start],$B13) -> 141755.18 | D13: =SUMIFS(tbl_rep_mon[net_sales],tbl_rep_mon[region_id],D$3,tbl_rep_mon[month_start],$B13) -> 254179.89 | E13: =SUMIFS(tbl_rep_mon[net_sales],tbl_rep_mon[region_id],E$3,tbl_rep_mon[month_start],$B13) -> 286815.39 | F13: =SUMIFS(tbl_rep_mon[net_sales],tbl_rep_mon[region_id],F$3,tbl_rep_mon[month_start],$B13) -> 367279.01 | H13: =$B13 -> 44470 | I13: =IFERROR(_xlfn.XLOOKUP(EDATE($B13,-12),$B$4:$B$63,C$4:C$63)*(1+target),_xlfn.XLOOKUP(I$3,region,seeding)) -> 150000 | J13: =IFERROR(_xlfn.XLOOKUP(EDATE($B13,-12),$B$4:$B$63,D$4:D$63)*(1+target),_xlfn.XLOOKUP(J$3,region,seeding)) -> 275000 | K13: =IFERROR(_xlfn.XLOOKUP(EDATE($B13,-12),$B$4:$B$63,E$4:E$63)*(1+target),_xlfn.XLOOKUP(K$3,region,seeding)) -> 300000 | L13: =IFERROR(_xlfn.XLOOKUP(EDATE($B13,-12),$B$4:$B$63,F$4:F$63)*(1+target),_xlfn.XLOOKUP(L$3,region,seeding)) -> 400000 | N13: =$B13 -> 44470 | O13: =C13/I13 -> 0.94503453 | P13: =D13/J13 -> 0.92429051 | Q13: =E13/K13 -> 0.9560513 | R13: =F13/L13 -> 0.91819753 | S13: =SUM(C13:F13)/SUM(I13:L13) -> 0.93335953
A14: =(YEAR($B14)) -> 2021 | B14: =EDATE($B13,1) -> 44501 | C14: =SUMIFS(tbl_rep_mon[net_sales],tbl_rep_mon[region_id],C$3,tbl_rep_mon[month_start],$B14) -> 119791 | D14: =SUMIFS(tbl_rep_mon[net_sales],tbl_rep_mon[region_id],D$3,tbl_rep_mon[month_start],$B14) -> 209062.93 | E14: =SUMIFS(tbl_rep_mon[net_sales],tbl_rep_mon[region_id],E$3,tbl_rep_mon[month_start],$B14) -> 277007.87 | F14: =SUMIFS(tbl_rep_mon[net_sales],tbl_rep_mon[region_id],F$3,tbl_rep_mon[month_start],$B14) -> 369094.71 | H14: =$B14 -> 44501 | I14: =IFERROR(_xlfn.XLOOKUP(EDATE($B14,-12),$B$4:$B$63,C$4:C$63)*(1+target),_xlfn.XLOOKUP(I$3,region,seeding)) -> 150000 | J14: =IFERROR(_xlfn.XLOOKUP(EDATE($B14,-12),$B$4:$B$63,D$4:D$63)*(1+target),_xlfn.XLOOKUP(J$3,region,seeding)) -> 275000 | K14: =IFERROR(_xlfn.XLOOKUP(EDATE($B14,-12),$B$4:$B$63,E$4:E$63)*(1+target),_xlfn.XLOOKUP(K$3,region,seeding)) -> 300000 | L14: =IFERROR(_xlfn.XLOOKUP(EDATE($B14,-12),$B$4:$B$63,F$4:F$63)*(1+target),_xlfn.XLOOKUP(L$3,region,seeding)) -> 400000 | N14: =$B14 -> 44501 | O14: =C14/I14 -> 0.79860667 | P14: =D14/J14 -> 0.76022884 | Q14: =E14/K14 -> 0.92335957 | R14: =F14/L14 -> 0.92273678 | S14: =SUM(C14:F14)/SUM(I14:L14) -> 0.86662801
A15: =(YEAR($B15)) -> 2021 | B15: =EDATE($B14,1) -> 44531 | C15: =SUMIFS(tbl_rep_mon[net_sales],tbl_rep_mon[region_id],C$3,tbl_rep_mon[month_start],$B15) -> 112784.27 | D15: =SUMIFS(tbl_rep_mon[net_sales],tbl_rep_mon[region_id],D$3,tbl_rep_mon[month_start],$B15) -> 248154.98 | E15: =SUMIFS(tbl_rep_mon[net_sales],tbl_rep_mon[region_id],E$3,tbl_rep_mon[month_start],$B15) -> 279773.29 | F15: =SUMIFS(tbl_rep_mon[net_sales],tbl_rep_mon[region_id],F$3,tbl_rep_mon[month_start],$B15) -> 372015.3 | H15: =$B15 -> 44531 | I15: =IFERROR(_xlfn.XLOOKUP(EDATE($B15,-12),$B$4:$B$63,C$4:C$63)*(1+target),_xlfn.XLOOKUP(I$3,region,seeding)) -> 150000 | J15: =IFERROR(_xlfn.XLOOKUP(EDATE($B15,-12),$B$4:$B$63,D$4:D$63)*(1+target),_xlfn.XLOOKUP(J$3,region,seeding)) -> 275000 | K15: =IFERROR(_xlfn.XLOOKUP(EDATE($B15,-12),$B$4:$B$63,E$4:E$63)*(1+target),_xlfn.XLOOKUP(K$3,region,seeding)) -> 300000 | L15: =IFERROR(_xlfn.XLOOKUP(EDATE($B15,-12),$B$4:$B$63,F$4:F$63)*(1+target),_xlfn.XLOOKUP(L$3,region,seeding)) -> 400000 | N15: =$B15 -> 44531 | O15: =C15/I15 -> 0.75189513 | P15: =D15/J15 -> 0.90238175 | Q15: =E15/K15 -> 0.93257763 | R15: =F15/L15 -> 0.93003825 | S15: =SUM(C15:F15)/SUM(I15:L15) -> 0.90020252
A16: =(YEAR($B16)) -> 2022 | B16: =EDATE($B15,1) -> 44562 | C16: =SUMIFS(tbl_rep_mon[net_sales],tbl_rep_mon[region_id],C$3,tbl_rep_mon[month_start],$B16) -> 120741.69 | D16: =SUMIFS(tbl_rep_mon[net_sales],tbl_rep_mon[region_id],D$3,tbl_rep_mon[month_start],$B16) -> 288883.96 | E16: =SUMIFS(tbl_rep_mon[net_sales],tbl_rep_mon[region_id],E$3,tbl_rep_mon[month_start],$B16) -> 318940.4 | F16: =SUMIFS(tbl_rep_mon[net_sales],tbl_rep_mon[region_id],F$3,tbl_rep_mon[month_start],$B16) -> 390978.87 | H16: =$B16 -> 44562 | I16: =IFERROR(_xlfn.XLOOKUP(EDATE($B16,-12),$B$4:$B$63,C$4:C$63)*(1+target),_xlfn.XLOOKUP(I$3,region,seeding)) -> 158990.24 | J16: =IFERROR(_xlfn.XLOOKUP(EDATE($B16,-12),$B$4:$B$63,D$4:D$63)*(1+target),_xlfn.XLOOKUP(J$3,region,seeding)) -> 280845.76 | K16: =IFERROR(_xlfn.XLOOKUP(EDATE($B16,-12),$B$4:$B$63,E$4:E$63)*(1+target),_xlfn.XLOOKUP(K$3,region,seeding)) -> 323855.92 | L16: =IFERROR(_xlfn.XLOOKUP(EDATE($B16,-12),$B$4:$B$63,F$4:F$63)*(1+target),_xlfn.XLOOKUP(L$3,region,seeding)) -> 431360.55 | N16: =$B16 -> 44562 | O16: =C16/I16 -> 0.75942833 | P16: =D16/J16 -> 1.0286214 | Q16: =E16/K16 -> 0.9848219 | R16: =F16/L16 -> 0.90638532 | S16: =SUM(C16:F16)/SUM(I16:L16) -> 0.93681655
A17: =(YEAR($B17)) -> 2022 | B17: =EDATE($B16,1) -> 44593 | C17: =SUMIFS(tbl_rep_mon[net_sales],tbl_rep_mon[region_id],C$3,tbl_rep_mon[month_start],$B17) -> 177532.73 | D17: =SUMIFS(tbl_rep_mon[net_sales],tbl_rep_mon[region_id],D$3,tbl_rep_mon[month_start],$B17) -> 317238.62 | E17: =SUMIFS(tbl_rep_mon[net_sales],tbl_rep_mon[region_id],E$3,tbl_rep_mon[month_start],$B17) -> 293343.48 | F17: =SUMIFS(tbl_rep_mon[net_sales],tbl_rep_mon[region_id],F$3,tbl_rep_mon[month_start],$B17) -> 430555.2 | H17: =$B17 -> 44593 | I17: =IFERROR(_xlfn.XLOOKUP(EDATE($B17,-12),$B$4:$B$63,C$4:C$63)*(1+target),_xlfn.XLOOKUP(I$3,region,seeding)) -> 162660.09 | J17: =IFERROR(_xlfn.XLOOKUP(EDATE($B17,-12),$B$4:$B$63,D$4:D$63)*(1+target),_xlfn.XLOOKUP(J$3,region,seeding)) -> 280978.23 | K17: =IFERROR(_xlfn.XLOOKUP(EDATE($B17,-12),$B$4:$B$63,E$4:E$63)*(1+target),_xlfn.XLOOKUP(K$3,region,seeding)) -> 358644.32 | L17: =IFERROR(_xlfn.XLOOKUP(EDATE($B17,-12),$B$4:$B$63,F$4:F$63)*(1+target),_xlfn.XLOOKUP(L$3,region,seeding)) -> 423306.48 | N17: =$B17 -> 44593 | O17: =C17/I17 -> 1.0914338 | P17: =D17/J17 -> 1.1290505 | Q17: =E17/K17 -> 0.81792311 | R17: =F17/L17 -> 1.0171241 | S17: =SUM(C17:F17)/SUM(I17:L17) -> 0.99435447
A18: =(YEAR($B18)) -> 2022 | B18: =EDATE($B17,1) -> 44621 | C18: =SUMIFS(tbl_rep_mon[net_sales],tbl_rep_mon[region_id],C$3,tbl_rep_mon[month_start],$B18) -> 175172.74 | D18: =SUMIFS(tbl_rep_mon[net_sales],tbl_rep_mon[region_id],D$3,tbl_rep_mon[month_start],$B18) -> 323813.52 | E18: =SUMIFS(tbl_rep_mon[net_sales],tbl_rep_mon[region_id],E$3,tbl_rep_mon[month_start],$B18) -> 361143.55 | F18: =SUMIFS(tbl_rep_mon[net_sales],tbl_rep_mon[region_id],F$3,tbl_rep_mon[month_start],$B18) -> 326518.06 | H18: =$B18 -> 44621 | I18: =IFERROR(_xlfn.XLOOKUP(EDATE($B18,-12),$B$4:$B$63,C$4:C$63)*(1+target),_xlfn.XLOOKUP(I$3,region,seeding)) -> 169352.89 | J18: =IFERROR(_xlfn.XLOOKUP(EDATE($B18,-12),$B$4:$B$63,D$4:D$63)*(1+target),_xlfn.XLOOKUP(J$3,region,seeding)) -> 288876.37 | K18: =IFERROR(_xlfn.XLOOKUP(EDATE($B18,-12),$B$4:$B$63,E$4:E$63)*(1+target),_xlfn.XLOOKUP(K$3,region,seeding)) -> 376129.2 | L18: =IFERROR(_xlfn.XLOOKUP(EDATE($B18,-12),$B$4:$B$63,F$4:F$63)*(1+target),_xlfn.XLOOKUP(L$3,region,seeding)) -> 444986.97 | N18: =$B18 -> 44621 | O18: =C18/I18 -> 1.0343652 | P18: =D18/J18 -> 1.1209415 | Q18: =E18/K18 -> 0.96015824 | R18: =F18/L18 -> 0.73376994 | S18: =SUM(C18:F18)/SUM(I18:L18) -> 0.92754298
A19: =(YEAR($B19)) -> 2022 | B19: =EDATE($B18,1) -> 44652 | C19: =SUMIFS(tbl_rep_mon[net_sales],tbl_rep_mon[region_id],C$3,tbl_rep_mon[month_start],$B19) -> 216558.09 | D19: =SUMIFS(tbl_rep_mon[net_sales],tbl_rep_mon[region_id],D$3,tbl_rep_mon[month_start],$B19) -> 343776.81 | E19: =SUMIFS(tbl_rep_mon[net_sales],tbl_rep_mon[region_id],E$3,tbl_rep_mon[month_start],$B19) -> 278373.66 | F19: =SUMIFS(tbl_rep_mon[net_sales],tbl_rep_mon[region_id],F$3,tbl_rep_mon[month_start],$B19) -> 441888.56 | H19: =$B19 -> 44652 | I19: =IFERROR(_xlfn.XLOOKUP(EDATE($B19,-12),$B$4:$B$63,C$4:C$63)*(1+target),_xlfn.XLOOKUP(I$3,region,seeding)) -> 148919.77 | J19: =IFERROR(_xlfn.XLOOKUP(EDATE($B19,-12),$B$4:$B$63,D$4:D$63)*(1+target),_xlfn.XLOOKUP(J$3,region,seeding)) -> 279216.53 | K19: =IFERROR(_xlfn.XLOOKUP(EDATE($B19,-12),$B$4:$B$63,E$4:E$63)*(1+target),_xlfn.XLOOKUP(K$3,region,seeding)) -> 346251.18 | L19: =IFERROR(_xlfn.XLOOKUP(EDATE($B19,-12),$B$4:$B$63,F$4:F$63)*(1+target),_xlfn.XLOOKUP(L$3,region,seeding)) -> 465638.55 | N19: =$B19 -> 44652 | O19: =C19/I19 -> 1.454193 | P19: =D19/J19 -> 1.2312194 | Q19: =E19/K19 -> 0.80396452 | R19: =F19/L19 -> 0.94899479 | S19: =SUM(C19:F19)/SUM(I19:L19) -> 1.0327179
